Workbook
Name ANCHO: [1]M.TELA!$H$4
Name FOTO: INDEX([1]IMAGENES!$A$2:$L$2,MATCH([1]TELA!$C$9,[1]IMAGENES!$A$1:$L$1,0))

Sheet Datos
A1: DATOS DEL PEDIDO | B1: Pedido
B2: Cliente
B3: Técnico
B4: Fecha solicitada
B5: Revisión
B6: Unidades totales
A8: MATERIAL | B8: Tela
B9: Cristal
B10: Lacado (estructura)
A12: MODELO | B12: Modelo | E12: =IF(COUNTIF(Descontos!$E$1:$AA$1,'Cálculos de medidas'!$C$2)=0,"Non existe este modelo","") -> Non existe este modelo
B13: Cofre
B14: Guía compensadora
B15: Mecanismo
B16: SWBS
B17: Entre paredes
A19: TOLDO 1 | B19: OF | E19: TOLDO 2 | F19: OF | I19: TOLDO 3 | J19: OF | M19: TOLDO 4 | N19: OF
B20: Frente superior | F20: Frente superior | J20: Frente superior | N20: Frente superior
B21: Frente inferior | F21: Frente inferior | J21: Frente inferior | N21: Frente inferior
B23: Saída esquerda | F23: Saída esquerda | J23: Saída esquerda | N23: Saída esquerda
B24: Saida dereita | F24: Saida dereita | J24: Saida dereita | N24: Saida dereita
B26: Diagonal 1 | F26: Diagonal 1 | J26: Diagonal 1 | N26: Diagonal 1
B27: Diagonal 2 | F27: Diagonal 2 | J27: Diagonal 2 | N27: Diagonal 2
A29: Hueco | B29: Dereita | C29: =IFERROR('Cálculos de escuadrado'!M3,"") | E29: Hueco | F29: Dereita | G29: =IFERROR('Cálculos de escuadrado'!M7,"") | I29: Hueco | J29: Dereita | K29: =IFERROR('Cálculos de escuadrado'!M11,"") | M29: Hueco | N29: Dereita | O29: =IFERROR('Cálculos de escuadrado'!M15,"")
B30: Esquerda | C30: =IFERROR('Cálculos de escuadrado'!M4,"") | F30: Esquerda | G30: =IFERROR('Cálculos de escuadrado'!M8,"") | J30: Esquerda | K30: =IFERROR('Cálculos de escuadrado'!M12,"") | N30: Esquerda | O30: =IFERROR('Cálculos de escuadrado'!M16,"")
B32: Erro na medida | C32: =IFERROR(_xlfn.IFS(ABS('Cálculos de escuadrado'!U3-Datos!C21)<=0.5,"<5mm",ABS('Cálculos de escuadrado'!U3-Datos!C21)<=1,"<1cm",ABS('Cálculos de escuadrado'!U3-Datos!C21>1),">1cm"),"") | F32: Erro na medida | G32: =IFERROR(_xlfn.IFS(ABS('Cálculos de escuadrado'!U7-Datos!G21)<=0.5,"<5mm",ABS('Cálculos de escuadrado'!U7-Datos!G21)<=1,"<1cm",ABS('Cálculos de escuadrado'!U7-Datos!G21>1),">1cm"),"") | J32: Erro na medida | K32: =IFERROR(_xlfn.IFS(ABS('Cálculos de escuadrado'!U11-Datos!K21)<=0.5,"<5mm",ABS('Cálculos de escuadrado'!U11-Datos!K21)<=1,"<1cm",ABS('Cálculos de escuadrado'!U11-Datos!K21)>1,">1cm"),"") | N32: Erro na medida | O32: =IFERROR(_xlfn.IFS('Cálculos de escuadrado'!U15-Datos!O21<=0.5,"<5mm",'Cálculos de escuadrado'!U15-Datos!O21<=1,"<1cm",'Cálculos de escuadrado'!U15-Datos!O21>1,">1cm"),"")
B34: Frente toldo: | C34: =C20+SUMIF(C29:C30,"<0") -> 0 | F34: Frente toldo: | G34: =G20+SUMIF(G29:G30,"<0") -> 0 | J34: Frente toldo: | K34: =K20+SUMIF(K29:K30,"<0") -> 0 | N34: Frente toldo: | O34: =O20+SUMIF(O29:O30,"<0") -> 0
C37: =IFERROR('Cálculos de escuadrado'!U3-Datos!C21,"") | G37: =IFERROR('Cálculos de escuadrado'!U7-G21,"") | K37: =IFERROR('Cálculos de escuadrado'!U11-Datos!K21,"") | O37: =IFERROR('Cálculos de escuadrado'!U15-Datos!O21,"")

Sheet Medidas Toldo 1
C2: OF | D2: =Datos!C19 -> 0 | F2: Pedido | G2: =Datos!C1 -> 0
C3: Cliente | D3: =Datos!C2 -> 0
C4: Técnico | D4: =Datos!C3 -> 0 | G4: Fecha fabric | H4: =Datos!C4 -> 0
C5: Revisión | D5: =Datos!C5 -> 0 | G5: Fecha | H5: =TEXT(NOW(),"dd/mm/aaa") -> 18/03/2026
B6: ="TOLDO 1"&" de "&Datos!C6 -> TOLDO 1 de
B9: TELA | C9: Frente | F9: =IF(Datos!C6<1,0,ROUNDDOWN('Cálculos de medidas'!J9,1)) -> 0 | G9: =ROUNDUP(ROUNDUP(F9/VLOOKUP(Datos!C8,'M TELAS'!B:C,2),0)*F10/100-IF(ISNUMBER(F11),1.4*ROUNDUP(F9/VLOOKUP(Datos!C8,'M TELAS'!B:C,2),0),0),1) -> #N/A | H9: mL
C10: Salida | F10: =IFERROR(ROUNDDOWN('Cálculos de medidas'!J10,1),0) -> 0
C11: Cristal | F11: =_xlfn.IFS(Datos!C9="NO","No",Datos!C9="SI",Características!O15) -> #N/A
B13: COFRE | C13: Cofre | F13: =ROUNDDOWN('Cálculos de medidas'!J11,1) -> #N/A
C14: Tubo enrolle | F14: =ROUNDDOWN('Cálculos de medidas'!J12,1) -> #N/A
C15: Tubo carga | F15: =ROUNDDOWN('Cálculos de medidas'!J13,1) -> #N/A
C16: Lastre | F16: =ROUNDDOWN('Cálculos de medidas'!J14,1) -> #N/A
F18: MFI | H18: MFD
B20: GUÍAS | C20: Perfil de guía pared | F20: =IFERROR(ROUNDDOWN('Cálculos de medidas'!J16,1),"") | H20: =IFERROR(ROUNDDOWN('Cálculos de medidas'!J20,1),"")
C21: Perfil guía interior ZIP Pared | F21: =IFERROR(ROUNDDOWN('Cálculos de medidas'!J17,1),"") | H21: =IFERROR(ROUNDDOWN('Cálculos de medidas'!J21,1),"")
C22: Guía compensación pared | F22: =IFERROR(ROUNDDOWN('Cálculos de medidas'!J22,1),"NO") -> NO | H22: =IFERROR(ROUNDDOWN('Cálculos de medidas'!J22,1),"NO") -> NO

Sheet Medidas Toldo 2
C2: OF | D2: =Datos!G19 -> 0 | F2: Pedido | G2: =Datos!C1 -> 0
C3: Cliente | D3: =Datos!C2 -> 0
C4: Técnico | D4: =Datos!C3 -> 0 | G4: Fecha fabric | H4: =Datos!C4 -> 0
C5: Revisión | D5: =Datos!C5 -> 0 | G5: Fecha | H5: =TEXT(NOW(),"dd/mm/aaa") -> 18/03/2026
B6: ="TOLDO 2"&" de "&Datos!C6 -> TOLDO 2 de
B9: TELA | C9: Frente | F9: =IF(Datos!C6<2,0,ROUNDDOWN('Cálculos de medidas'!J33,1)) -> 0 | G9: =ROUNDUP(ROUNDUP(F9/VLOOKUP(Datos!C8,'M TELAS'!B:C,2),0)*F10/100-IF(ISNUMBER(F11),1.4*ROUNDUP(F9/VLOOKUP(Datos!C8,'M TELAS'!B:C,2),0),0),1) -> #N/A | H9: mL
C10: Salida | F10: =IFERROR(ROUNDDOWN('Cálculos de medidas'!J34,1),0) -> 0
C11: Cristal | F11: =_xlfn.IFS(Datos!C9="NO","No",Datos!C9="SI",Características!O16) -> #N/A
B13: COFRE | C13: Cofre | F13: =ROUNDDOWN('Cálculos de medidas'!J35,1) -> #N/A
C14: Tubo enrolle | F14: =ROUNDDOWN('Cálculos de medidas'!J36,1) -> #N/A
C15: Tubo carga | F15: =ROUNDDOWN('Cálculos de medidas'!J37,1) -> #N/A
C16: Lastre | F16: =ROUNDDOWN('Cálculos de medidas'!J38,1) -> #N/A
F18: MFI | H18: MFD
B20: GUÍAS | C20: Perfil de guía pared | F20: =IFERROR(ROUNDDOWN('Cálculos de medidas'!J40,1),"") | H20: =IFERROR(ROUNDDOWN('Cálculos de medidas'!J44,1),"")
C21: Perfil guía interior ZIP Pared | F21: =IFERROR(ROUNDDOWN('Cálculos de medidas'!J41,1),"") | H21: =IFERROR(ROUNDDOWN('Cálculos de medidas'!J45,1),"")
C22: Guía compensación pared | F22: =IFERROR(ROUNDDOWN('Cálculos de medidas'!J42,1),"NO") -> NO | H22: =IFERROR(ROUNDDOWN('Cálculos de medidas'!J46,1),"NO") -> NO

Sheet Medidas Toldo 3
C2: OF | D2: =Datos!K19 -> 0 | F2: Pedido | G2: =Datos!C1 -> 0
C3: Cliente | D3: =Datos!C2 -> 0
C4: Técnico | D4: =Datos!C3 -> 0 | G4: Fecha fabric | H4: =Datos!C4 -> 0
C5: Revisión | D5: =Datos!C5 -> 0 | G5: Fecha | H5: =TEXT(NOW(),"dd/mm/aaa") -> 18/03/2026
B6: ="TOLDO 3"&" de "&Datos!C6 -> TOLDO 3 de
B9: TELA | C9: Frente | F9: =IF(Datos!C6<3,0,ROUNDDOWN('Cálculos de medidas'!J57,1)) -> 0 | G9: =ROUNDUP(ROUNDUP(F9/VLOOKUP(Datos!C8,'M TELAS'!B:C,2),0)*F10/100-IF(ISNUMBER(F11),1.4*ROUNDUP(F9/VLOOKUP(Datos!C8,'M TELAS'!B:C,2),0),0),1) -> #N/A | H9: mL
C10: Salida | F10: =IFERROR(ROUNDDOWN('Cálculos de medidas'!J58,1),0) -> 0
C11: Cristal | F11: =_xlfn.IFS(Datos!C9="NO","No",Datos!C9="SI",Características!O17) -> #N/A
B13: COFRE | C13: Cofre | F13: =ROUNDDOWN('Cálculos de medidas'!J59,1) -> #N/A
C14: Tubo enrolle | F14: =ROUNDDOWN('Cálculos de medidas'!J60,1) -> #N/A
C15: Tubo carga | F15: =ROUNDDOWN('Cálculos de medidas'!J61,1) -> #N/A
C16: Lastre | F16: =ROUNDDOWN('Cálculos de medidas'!J62,1) -> #N/A
F18: MFI | H18: MFD
B20: GUÍAS | C20: Perfil de guía pared | F20: =IFERROR(ROUNDDOWN('Cálculos de medidas'!J64,1),"") | H20: =IFERROR(ROUNDDOWN('Cálculos de medidas'!J68,1),"")
C21: Perfil guía interior ZIP Pared | F21: =IFERROR(ROUNDDOWN('Cálculos de medidas'!J65,1),"") | H21: =IFERROR(ROUNDDOWN('Cálculos de medidas'!J69,1),"")
C22: Guía compensación pared | F22: =IFERROR(ROUNDDOWN('Cálculos de medidas'!J66,1),"NO") -> NO | H22: =IFERROR(ROUNDDOWN('Cálculos de medidas'!J70,1),"NO") -> NO

Sheet Medidas Toldo 4
C2: OF | D2: =Datos!O19 -> 0 | F2: Pedido | G2: =Datos!C1 -> 0
C3: Cliente | D3: =Datos!C2 -> 0
C4: Técnico | D4: =Datos!C3 -> 0 | G4: Fecha fabric | H4: =Datos!C4 -> 0
C5: Revisión | D5: =Datos!C5 -> 0 | G5: Fecha | H5: =TEXT(NOW(),"dd/mm/aaa") -> 18/03/2026
B6: ="TOLDO 4"&" de "&Datos!C6 -> TOLDO 4 de
B9: TELA | C9: Frente | F9: =IF(Datos!C6<4,0,ROUNDDOWN('Cálculos de medidas'!J81,1)) -> 0 | G9: =ROUNDUP(ROUNDUP(F9/VLOOKUP(Datos!C8,'M TELAS'!B:C,2),0)*F10/100-IF(ISNUMBER(F11),1.4*ROUNDUP(F9/VLOOKUP(Datos!C8,'M TELAS'!B:C,2),0),0),1) -> #N/A | H9: mL
C10: Salida | F10: =IFERROR(ROUNDDOWN('Cálculos de medidas'!J82,1),0) -> 0
C11: Cristal | F11: =_xlfn.IFS(Datos!C9="NO","No",Datos!C9="SI",Características!O18) -> #N/A
B13: COFRE | C13: Cofre | F13: =ROUNDDOWN('Cálculos de medidas'!J83,1) -> #N/A
C14: Tubo enrolle | F14: =ROUNDDOWN('Cálculos de medidas'!J84,1) -> #N/A
C15: Tubo carga | F15: =ROUNDDOWN('Cálculos de medidas'!J85,1) -> #N/A
C16: Lastre | F16: =ROUNDDOWN('Cálculos de medidas'!J86,1) -> #N/A
F18: MFI | H18: MFD
B20: GUÍAS | C20: Perfil de guía pared | F20: =IFERROR(ROUNDDOWN('Cálculos de medidas'!J88,1),"") | H20: =IFERROR(ROUNDDOWN('Cálculos de medidas'!J92,1),"")
C21: Perfil guía interior ZIP Pared | F21: =IFERROR(ROUNDDOWN('Cálculos de medidas'!J89,1),"") | H21: =IFERROR(ROUNDDOWN('Cálculos de medidas'!J93,1),"")
C22: Guía compensación pared | F22: =IFERROR(ROUNDDOWN('Cálculos de medidas'!J90,1),"NO") -> NO | H22: =IFERROR(ROUNDDOWN('Cálculos de medidas'!J94,1),"NO") -> NO

Sheet M TELAS
A1: REFERENCIA | B1: DESCRIPCION | C1: ANCHO | D1: MATERIAL | E1: COLOR
A2: ACRILI2427P120 | B2: ACR ACQUAMARINA | C2: 120 | D2: ACR | E2: ACQUAMARINA
A3: ACRILI2807P120 | B3: ACR ACUARIO | C3: 120 | D3: ACR | E3: ACUARIO
A4: ACRILI2051P120 | B4: ACR ADMIRAL | C4: 120 | D4: ACR | E4: ADMIRAL
A5: ACRILI2051P153 | B5: ACR ADMIRAL | C5: 153 | D5: ACR | E5: ADMIRAL
A6: ACRILI3012P120 | B6: ACR AFRICA | C6: 120 | D6: ACR | E6: AFRICA
A7: ACRILI2562P120 | B7: ACR ALABAMA | C7: 120 | D7: ACR | E7: ALABAMA
A8: ACRILI8157P120 | B8: ACR ALABASTRO | C8: 120 | D8: ACR | E8: ALABASTRO
A9: ACRILI1472P120 | B9: ACR ALAMO | C9: 120 | D9: ACR | E9: ALAMO
A10: ACRILI2819P120 | B10: ACR ALOE | C10: 120 | D10: ACR | E10: ALOE
A11: ACRILI2031P120 | B11: ACR ALSACIA | C11: 120 | D11: ACR | E11: ALSACIA
A12: ACRILI2013P120 | B12: ACR AMARILLO | C12: 120 | D12: ACR | E12: AMARILLO
A13: ACRILI2015P120 | B13: ACR AMARILLO N | C13: 120 | D13: ACR | E13: AMARILLO N
... A251: G650AM03P250 | B251: PVC 650 AMARILLO 1003 | C251: 250 | D251: PVC 650 | E251: AMARILLO 1003
A252: B8000AM21P250 | B252: PVC 650 AMARILLO 1021 | C252: 250 | E252: AMARILLO 1021
A253: G650AZ15P250 | B253: PVC 650 AZUL 5015 | C253: 250 | D253: PVC 650 | E253: AZUL 5015
A254: B8000AZ0SP250 | B254: PVC 650 AZUL 5032 | C254: 250 | E254: AZUL 5032
A255: G650AZEUP250 | B255: PVC 650 AZUL EUROPA | C255: 250 | D255: PVC 650 | E255: AZUL EUROPA
A256: LAC640AZ15P300 | B256: PVC 650 AZUL EUROPA | C256: 250 | D256: PVC 650 | E256: AZUL EUROPA
A257: LAC640BL10P250 | B257: PVC 650 BLANCO | C257: 250 | D257: PVC 650 | E257: BLANCO
A258: LAC650BLANP250 | B258: PVC 650 BLANCO | C258: 250 | D258: PVC 650 IGN | E258: BLANCO
A259: G650CR14P250 | B259: PVC 650 CREMA | C259: 250 | D259: PVC 650 | E259: CREMA
A260: B8000GRCLP250 | B260: PVC 650 GRIS 7001 | C260: 250 | D260: PVC 650 | E260: GRIS 7001
A261: G650GR38P250 | B261: PVC 650 GRIS 7038 | C261: 250 | D261: PVC 650 | E261: GRIS 7038
A262: B8000GROSP250 | B262: PVC 650 GRIS 7024 | C262: 250 | D262: PVC 650 | E262: GRIS 7024
A263: G650GR30P250 | B263: PVC 650 GRIS 7030 | C263: 250 | D263: PVC 650 | E263: GRIS 7030
A264: G650GR37P250 | B264: PVC 650 GRIS 7037 | C264: 250 | D264: PVC 650 | E264: GRIS 7037
A265: B8000GRMEP250 | B265: PVC 650 GRIS 7060 | C265: 250 | D265: PVC 650 | E265: GRIS 7060
A266: B8000GRALP250 | B266: PVC 650 GRIS ALUMINIO | C266: 250 | D266: PVC 650 | E266: GRIS ALUMINIO
... A294: SOLTIS9250HAP177 | B294: SOLTIS 92 HABANA | C294: 267 | D294: SOLTIS 92 | E294: HABANA
A295: SOLTIS920268P177 | B295: SOLTIS 92 50268 | C295: 267 | D295: SOLTIS 92
A296: SOLTIS92AMCLP177 | B296: SOLTIS 92 AMARILLO LIMON | C296: 267 | D296: SOLTIS 92 | E296: AMARILLO LIMON
A297: SOLTIS92ARENP177 | B297: SOLTIS 92 ARENA | C297: 267 | D297: SOLTIS 92 | E297: ARENA
A298: SOLTIS92AZULP177 | B298: SOLTIS 92 AZUL | C298: 267 | D298: SOLTIS 92 | E298: AZUL
A299: SOLTIS92CAFEP177 | B299: SOLTIS 92 CAFÉ | C299: 267 | D299: SOLTIS 92 | E299: CAFE
A300: SOLTIS92GRMEP177 | B300: SOLTIS 92 GRIS MEDIO | C300: 267 | D300: SOLTIS 92 | E300: GRIS MEDIO
A301: SOLTIS92GROSP177 | B301: SOLTIS 92 GRIS OSCURO | C301: 267 | D301: SOLTIS 92 | E301: GRIS OSCURO
A302: SOLTIS92MRROP177 | B302: SOLTIS 92 MARRON | C302: 267 | D302: SOLTIS 92 | E302: MARRON
A303: SOLTIS92NEGRP177 | B303: SOLTIS 92 NEGRO | C303: 267 | D303: SOLTIS 92 | E303: NEGRO
A304: SOLTIS92NUBP177 | B304: SOLTIS 92 NUBE | C304: 267 | D304: SOLTIS 92 | E304: NUBE
...

Sheet Cálculos de escuadrado
C1: Cálculo do escuadro | Q1: Verificaicón
C2: Semiperímetro | E2: Área | G2: Altura | I2: Holgura | K2: Desfase | M2: Dir holgura | O2: Desconto frente | Q2: Sep. alturas | S2: Dif alturas | U2: Frente medido
A3: 1 | B3: Triángulo 1: | C3: =(Datos!C$20+Datos!C$26+Datos!C$23)/2 -> 0 | E3: =SQRT(C3*(C3-Datos!C$20)*(C3-Datos!C$26)*(C3-Datos!C$23)) -> 0 | G3: =2*E3/Datos!C$20 -> #DIV/0! | I3: =SQRT(Datos!C$23^2-G3^2) -> #DIV/0! | K3: =DEGREES(ACOS((Datos!C$23^2+Datos!C$20^2-Datos!C$26^2)/(2*Datos!C$23*Datos!C$20))) -> #DIV/0! | M3: =IF('Cálculos de escuadrado'!$K3>90,'Cálculos de escuadrado'!$I3,-'Cálculos de escuadrado'!$I3) -> #DIV/0! | O3: =SUMIF(M3:M4,"<0",M3:M4) -> 0 | Q3: =Datos!C20+'Cálculos de escuadrado'!M3+'Cálculos de escuadrado'!M4 -> #DIV/0! | S3: =G3-G4 -> #DIV/0! | U3: =SQRT(Q3^2+S3^2) -> #DIV/0! | W3: =SUMIF(M3:M4,"<0") -> 0
B4: Triángulo 2: | C4: =(Datos!C$20+Datos!C$27+Datos!C$24)/2 -> 0 | E4: =SQRT(C4*(C4-Datos!C$20)*(C4-Datos!C$27)*(C4-Datos!C$24)) -> 0 | G4: =2*E4/Datos!C$20 -> #DIV/0! | I4: =SQRT(Datos!C$24^2-G4^2) -> #DIV/0! | K4: =DEGREES(ACOS((Datos!C$24^2+Datos!C$20^2-Datos!C$27^2)/(2*Datos!C$24*Datos!C$20))) -> #DIV/0! | M4: =IF('Cálculos de escuadrado'!$K4>90,'Cálculos de escuadrado'!$I4,-'Cálculos de escuadrado'!$I4) -> #DIV/0!
A7: 2 | B7: Triángulo 1: | C7: =(Datos!G$20+Datos!G$26+Datos!G$23)/2 -> 0 | E7: =SQRT(C7*(C7-Datos!G$20)*(C7-Datos!G$26)*(C7-Datos!G$23)) -> 0 | G7: =2*E7/Datos!G$20 -> #DIV/0! | I7: =SQRT(Datos!G$23^2-G7^2) -> #DIV/0! | K7: =DEGREES(ACOS((Datos!G$23^2+Datos!G$20^2-Datos!G$26^2)/(2*Datos!G$23*Datos!G$20))) -> #DIV/0! | M7: =IF('Cálculos de escuadrado'!$K7>90,'Cálculos de escuadrado'!$I7,-'Cálculos de escuadrado'!$I7) -> #DIV/0! | O7: =SUMIF(M3:M4,"<0",M3:M4) -> 0 | Q7: =Datos!G20+'Cálculos de escuadrado'!M7+'Cálculos de escuadrado'!M8 -> #DIV/0! | S7: =G7-G8 -> #DIV/0! | U7: =SQRT(Q7^2+S7^2) -> #DIV/0!
B8: Triángulo 2: | C8: =(Datos!G$20+Datos!G$27+Datos!G$24)/2 -> 0 | E8: =SQRT(C8*(C8-Datos!G$20)*(C8-Datos!G$27)*(C8-Datos!G$24)) -> 0 | G8: =2*E8/Datos!G$20 -> #DIV/0! | I8: =SQRT(Datos!G$24^2-G8^2) -> #DIV/0! | K8: =DEGREES(ACOS((Datos!G$24^2+Datos!G$20^2-Datos!G$27^2)/(2*Datos!G$24*Datos!G$20))) -> #DIV/0! | M8: =IF('Cálculos de escuadrado'!$K8>90,'Cálculos de escuadrado'!$I8,-'Cálculos de escuadrado'!$I8) -> #DIV/0!
A11: 2 | B11: Triángulo 1: | C11: =(Datos!K$20+Datos!K$26+Datos!K$23)/2 -> 0 | E11: =SQRT(C11*(C11-Datos!K$20)*(C11-Datos!K$26)*(C11-Datos!K$23)) -> 0 | G11: =2*E11/Datos!K$20 -> #DIV/0! | I11: =SQRT(Datos!K$23^2-G11^2) -> #DIV/0! | K11: =DEGREES(ACOS((Datos!K$23^2+Datos!K$20^2-Datos!K$26^2)/(2*Datos!K$23*Datos!K$20))) -> #DIV/0! | M11: =IF('Cálculos de escuadrado'!$K11>90,'Cálculos de escuadrado'!$I11,-'Cálculos de escuadrado'!$I11) -> #DIV/0! | O11: =SUMIF(M3:M4,"<0",M3:M4) -> 0 | Q11: =Datos!K20+'Cálculos de escuadrado'!M11+'Cálculos de escuadrado'!M12 -> #DIV/0! | S11: =G11-G12 -> #DIV/0! | U11: =SQRT(Q11^2+S11^2) -> #DIV/0!
B12: Triángulo 2: | C12: =(Datos!K$20+Datos!K$27+Datos!K$24)/2 -> 0 | E12: =SQRT(C12*(C12-Datos!K$20)*(C12-Datos!K$27)*(C12-Datos!K$24)) -> 0 | G12: =2*E12/Datos!K$20 -> #DIV/0! | I12: =SQRT(Datos!K$24^2-G12^2) -> #DIV/0! | K12: =DEGREES(ACOS((Datos!K$24^2+Datos!K$20^2-Datos!K$27^2)/(2*Datos!K$24*Datos!K$20))) -> #DIV/0! | M12: =IF('Cálculos de escuadrado'!$K12>90,'Cálculos de escuadrado'!$I12,-'Cálculos de escuadrado'!$I12) -> #DIV/0!
A15: 2 | B15: Triángulo 1: | C15: =(Datos!O$20+Datos!O$26+Datos!O$23)/2 -> 0 | E15: =SQRT(C15*(C15-Datos!O$20)*(C15-Datos!O$26)*(C15-Datos!O$23)) -> 0 | G15: =2*E15/Datos!O$20 -> #DIV/0! | I15: =SQRT(Datos!O$23^2-G15^2) -> #DIV/0! | K15: =DEGREES(ACOS((Datos!O$23^2+Datos!O$20^2-Datos!O$26^2)/(2*Datos!O$23*Datos!O$20))) -> #DIV/0! | M15: =IF('Cálculos de escuadrado'!$K15>90,'Cálculos de escuadrado'!$I15,-'Cálculos de escuadrado'!$I15) -> #DIV/0! | O15: =SUMIF(M3:M4,"<0",M3:M4) -> 0 | Q15: =Datos!O20+'Cálculos de escuadrado'!M15+'Cálculos de escuadrado'!M16 -> #DIV/0! | S15: =G15-G16 -> #DIV/0! | U15: =SQRT(Q15^2+S15^2) -> #DIV/0!
B16: Triángulo 2: | C16: =(Datos!O$20+Datos!O$27+Datos!O$24)/2 -> 0 | E16: =SQRT(C16*(C16-Datos!O$20)*(C16-Datos!O$27)*(C16-Datos!O$24)) -> 0 | G16: =2*E16/Datos!O$20 -> #DIV/0! | I16: =SQRT(Datos!O$24^2-G16^2) -> #DIV/0! | K16: =DEGREES(ACOS((Datos!O$24^2+Datos!O$20^2-Datos!O$27^2)/(2*Datos!O$24*Datos!O$20))) -> #DIV/0! | M16: =IF('Cálculos de escuadrado'!$K16>90,'Cálculos de escuadrado'!$I16,-'Cálculos de escuadrado'!$I16) -> #DIV/0!

Sheet Descontos
A1: 1 | E1: 00000 | F1: 00010 | G1: 00100-Non existe | H1: 00110 | I1: 00200 | J1: 00210 | K1: 00201 | L1: 00211 | M1: 01000 | N1: 01010 | O1: 10000 | P1: 10010 | Q1: 10001 | R1: 10011 | S1: 10100-Sen uso | T1: 10110 | U1: 10101-Sen uso | V1: 10111 | W1: 10200-Sen uso | X1: 10210-Sen uso | Y1: 11000 | Z1: 11010 | AA1: 20010
A2: 2 | D2: Modelo | E2: 110 | O2: 130 | AA2: 150
A3: 3 | D3: Cofre | E3: Cofre | M3: Sin cofre | O3: Cofre | Y3: Sin cofre | AA3: Cofre
A4: 4 | D4: Guía | E4: Sin guía | G4: Guía pequena | I4: Guía (sin SWBS) | K4: Guía (Con SWBS) | M4: Módulo simple | O4: Sin guía | Q4: Sin guía, CON SWBS | S4: Guía pequena sin SWBS | U4: Guía pequena CON SWBS | W4: Guía | Y4: Sen guía
A5: 5 | B5: Nomenclatura BAT | C5: Nomenclatura TGM | D5: Mecanismo | E5: Máquina | F5: Motor | G5: Máquina | H5: Motor | I5: Máquina | J5: Motor | K5: Máquina | L5: Motor | M5: Máquina | N5: Motor | O5: Máquina | P5: Motor | Q5: Máquina | R5: Motor | S5: Máquina | T5: Motor | U5: Máquina | V5: Motor | W5: Máquina | X5: Motor | Y5: Máquina | Z5: Motor | AA5: Motor
A6: 6 | B6: Telón | C6: Frente | E6: 9 | F6: 9 | G6: x | H6: 5.2 | I6: 9.7 | J6: 8.5 | K6: 10.6 | L6: 9.4 | M6: 9 | N6: 9 | O6: 9 | P6: 9 | Q6: 9.4 | R6: 9.4 | S6: x | T6: 5.2 | U6: x | V6: 5.2 | Y6: 9 | AA6: 9
A7: 7 | C7: Caída
A8: 8 | B8: Cofre y tapa | C8: Cofre | E8: 1.4 | F8: 1.4 | G8: x | H8: 1.4 | I8: 1.4 | J8: 1.4 | K8: 1.4 | L8: 1.4 | M8: 1.4 | O8: 1.4 | P8: 1.4 | Q8: 1.4 | R8: 1.4 | S8: x | T8: 1.4 | U8: x | V8: 1.4 | AA8: 0.6
A9: 9 | B9: Tubo enrollador | C9: Tubo enrolle | E9: 15.8 | F9: 14.8 | G9: x | H9: 14.6 | I9: 15.5 | J9: 14.8 | K9: 15.5 | L9: 14.8 | M9: 15.8 | N9: 14.8 | O9: 15.8 | P9: 14.8 | Q9: 15.8 | R9: 14.8 | S9: x | T9: 14.6 | U9: x | V9: 14.6 | Y9: 15.8 | AA9: 16.8
A10: 10 | B10: Terminal de caída | C10: Tubo carga | E10: 13.2 | F10: 13.2 | G10: x | H10: 9.4 | I10: 14.6 | J10: 13.4 | K10: 14.6 | L10: 13.4 | M10: 13.2 | N10: 13.2 | O10: 13.2 | P10: 13.2 | Q10: 13.2 | R10: 13.2 | S10: x | T10: 9.4 | U10: x | V10: 8.8 | Y10: 13.2 | AA10: 13.2
A11: 11 | B11: Lastre | C11: Lastre | E11: 26.2 | F11: 26.2 | G11: x | H11: 22.4 | I11: 27.6 | J11: 26.4 | K11: 44.6 | L11: 33.4 | M11: 26.2 | N11: 26.2 | O11: 26.2 | P11: 26.2 | Q11: 33.2 | R11: 33.2 | S11: x | T11: 22.4 | U11: x | V11: 28.8 | Y11: 26.2 | AA11: 27.8
A12: 12 | B12: Guía compensación pared | E12: x | F12: x | G12: x | H12: x | I12: 11.2 | J12: 11.2 | K12: 11.2 | L12: 11.2 | M12: x | N12: x | O12: x | P12: x | Q12: x | R12: x | S12: x | T12: x | U12: x | V12: x | AA12: x
A13: 13 | B13: Guía compensación techo | E13: x | F13: x | G13: x | H13: x | I13: 11.4 | J13: 11.4 | K13: 11.4 | L13: 11.4 | M13: x | N13: x | O13: x | P13: x | Q13: x | R13: x | S13: x | T13: x | U13: x | V13: x | AA13: x
A14: 14 | B14: Perfil de guía pared | E14: 12 | F14: 12 | G14: x | H14: 12 | I14: 12 | J14: 12 | K14: 12 | L14: 12 | M14: 11.3 | N14: 11.3 | O14: 13.7 | P14: 13.7 | Q14: 13.7 | R14: 13.7 | S14: x | T14: 13.7 | U14: x | V14: 13.7 | AA14: 15.5
A15: 15 | B15: Perfil de guía techo | E15: 12.2 | F15: 12.2 | G15: x | H15: 12.2 | I15: 12.2 | J15: 12.2 | K15: 12.2 | L15: 12.2 | M15: 12.8 | N15: 12.8 | O15: 13.9 | P15: 13.9 | Q15: 13.9 | R15: 13.9 | S15: x | T15: 13.9 | U15: x | V15: 13.9 | AA15: 15.5
A16: 16 | B16: Perfil guía interior ZIP Pared | I16: 12 | J16: 12 | K16: 18.1 | L16: 18.1 | O16: 13.7 | P16: 13.7 | Q16: 19.8 | R16: 19.8 | S16: x | T16: 13.7 | U16: x | V16: 19.8
A17: 17 | B17: Perfil guía interior ZIP Techo | I17: 12.2 | J17: 12.2 | K17: 18.3 | L17: 18.3 | O17: 13.9 | P17: 13.9 | Q17: 20 | R17: 20 | S17: x | T17: 13.9 | U17: x | V17: 20
A18: 18 | B18: Terminal compensador | K18: 14.8 | L18: 13.6 | Q18: 13.4 | R18: 13.4 | V18: 9
I21: Hai unha anotación na captura de"non descontar"?
B24: Elemento | C24: Código artículo
A25: 25 | C25: Pieza 1 | D25: 1 | E25: 1 | F25: 0 | G25: 0 | H25: 3 | I25: 0 | J25: 0 | K25: 1 | L25: 0 | M25: 2 | N25: 1 | O25: 1 | P25: 0
A26: 26 | C26: Pieza 2 | D26: 2 | E26: 2 | F26: 0 | G26: 1 | H26: 0 | I26: 0 | J26: 1 | K26: 2 | L26: 1 | M26: 2 | N26: 2 | O26: 1 | P26: 1
A27: 27 | C27: Pieza 3 | D27: 3 | E27: 0 | F27: 0 | G27: 1 | H27: 1 | I27: 0 | J27: 1 | K27: 0 | L27: 2 | M27: 1 | N27: 2 | O27: 2 | P27: 1
A28: 28 | C28: Pieza 4 | D28: 0 | E28: 1 | F28: 0 | G28: 2 | H28: 2 | I28: 1 | J28: 2 | K28: 1 | L28: 3 | M28: 0 | N28: 2 | O28: 2 | P28: 2
A29: 29 | C29: Pieza 5 | D29: 1 | E29: 2 | F29: 1 | G29: 2 | H29: 3 | I29: 1 | J29: 0 | K29: 2 | L29: 0 | M29: 0 | N29: 1 | O29: 2 | P29: 2
A30: 30 | C30: Pieza 6 | D30: 2 | E30: 3 | F30: 1 | G30: 2 | H30: 0 | I30: 2 | J30: 1 | K30: 3 | L30: 1 | M30: 0 | N30: 0 | O30: 1 | P30: 2
A31: 31 | C31: Pieza 7 | D31: 3 | E31: 0 | F31: 2 | G31: 1 | H31: 1 | I31: 0 | J31: 2 | K31: 0 | L31: 2 | M31: 0 | N31: 0 | O31: 0 | P31: 1
A32: 32 | C32: Pieza 8 | D32: 0 | E32: 1 | F32: 0 | G32: 0 | H32: 1 | I32: 1 | J32: 3 | K32: 1 | L32: 3 | M32: 1 | N32: 0 | O32: 0 | P32: 0
A33: 33 | C33: Pieza 9 | D33: 1 | E33: 2 | F33: 1 | G33: 0 | H33: 2 | I33: 2 | J33: 0 | K33: 2 | L33: 0 | M33: 1 | N33: 0 | O33: 0 | P33: 0
A34: 34 | C34: Pieza 10 | D34: 1 | E34: 3 | F34: 2 | G34: 0 | H34: 2 | I34: 3 | J34: 1 | K34: 3 | L34: 1 | M34: 2 | N34: 1 | O34: 0 | P34: 0
A35: 35 | C35: Pieza 11 | D35: 2 | E35: 0 | F35: 3 | G35: 0 | H35: 2 | I35: 0 | J35: 2 | K35: 0 | L35: 1 | M35: 0 | N35: 1 | O35: 1 | P35: 0
A36: 36 | C36: Pieza 12 | D36: 2 | E36: 1 | F36: 0 | G36: 1 | H36: 1 | I36: 1 | J36: 3 | K36: 1 | L36: 2 | M36: 1 | N36: 2 | O36: 1 | P36: 1
... A46: 46 | C46: Pieza 22 | D46: 0 | E46: 1 | F46: 1 | G46: 3 | H46: 2 | I46: 0 | J46: 0 | K46: 1 | L46: 2 | M46: 2 | N46: 1 | O46: 0 | P46: 3

Sheet Escandallo
A1: OF | B1: ARTICULO | C1: CANTIDAD
A2: =Datos!$C$19 -> 0 | B2: =INDEX('M TELAS'!A:A,MATCH(Datos!C8,'M TELAS'!B:B,0)) -> #N/A | C2: =IFERROR('Medidas Toldo 1'!G9,0) -> 0
A3: =Datos!$C$19 -> 0
A4: =Datos!$C$19 -> 0 | B4: Pieza 1 | C4: =IF(A4<>0,HLOOKUP('Cálculos de medidas'!$C$2,Descontos!$E$1:$AA$47,Descontos!A25),0) -> 0
A5: =Datos!$C$19 -> 0 | B5: Pieza 2 | C5: =IF(A5<>0,HLOOKUP('Cálculos de medidas'!$C$2,Descontos!$E$1:$AA$47,Descontos!A26),0) -> 0
A6: =Datos!$C$19 -> 0 | B6: Pieza 3 | C6: =IF(A6<>0,HLOOKUP('Cálculos de medidas'!$C$2,Descontos!$E$1:$AA$47,Descontos!A27),0) -> 0
A7: =Datos!$C$19 -> 0 | B7: Pieza 4 | C7: =IF(A7<>0,HLOOKUP('Cálculos de medidas'!$C$2,Descontos!$E$1:$AA$47,Descontos!A28),0) -> 0
A8: =Datos!$C$19 -> 0 | B8: Pieza 5 | C8: =IF(A8<>0,HLOOKUP('Cálculos de medidas'!$C$2,Descontos!$E$1:$AA$47,Descontos!A29),0) -> 0
A9: =Datos!$C$19 -> 0 | B9: Pieza 6 | C9: =IF(A9<>0,HLOOKUP('Cálculos de medidas'!$C$2,Descontos!$E$1:$AA$47,Descontos!A30),0) -> 0
A10: =Datos!$C$19 -> 0 | B10: Pieza 7 | C10: =IF(A10<>0,HLOOKUP('Cálculos de medidas'!$C$2,Descontos!$E$1:$AA$47,Descontos!A31),0) -> 0
A11: =Datos!$C$19 -> 0 | B11: Pieza 8 | C11: =IF(A11<>0,HLOOKUP('Cálculos de medidas'!$C$2,Descontos!$E$1:$AA$47,Descontos!A32),0) -> 0
A12: =Datos!$C$19 -> 0 | B12: Pieza 9 | C12: =IF(A12<>0,HLOOKUP('Cálculos de medidas'!$C$2,Descontos!$E$1:$AA$47,Descontos!A33),0) -> 0
A13: =Datos!$C$19 -> 0 | B13: Pieza 10 | C13: =IF(A13<>0,HLOOKUP('Cálculos de medidas'!$C$2,Descontos!$E$1:$AA$47,Descontos!A34),0) -> 0
A14: =Datos!$C$19 -> 0 | B14: Pieza 11 | C14: =IF(A14<>0,HLOOKUP('Cálculos de medidas'!$C$2,Descontos!$E$1:$AA$47,Descontos!A35),0) -> 0
A15: =Datos!$C$19 -> 0 | B15: Pieza 12 | C15: =IF(A15<>0,HLOOKUP('Cálculos de medidas'!$C$2,Descontos!$E$1:$AA$47,Descontos!A36),0) -> 0
... A25: =Datos!$C$19 -> 0 | B25: Pieza 22 | C25: =IF(A25<>0,HLOOKUP('Cálculos de medidas'!$C$2,Descontos!$E$1:$AA$47,Descontos!A46),0) -> 0
A27: OF | B27: ARTICULO | C27: CANTIDAD
A28: =Datos!$G$19 -> 0 | B28: =INDEX('M TELAS'!A:A,MATCH(Datos!C8,'M TELAS'!B:B,0)) -> #N/A | C28: =IFERROR('Medidas Toldo 2'!G9,0) -> 0
A29: =Datos!$G$19 -> 0
A30: =Datos!$G$19 -> 0 | B30: Pieza 1 | C30: =IF(A30<>0,HLOOKUP('Cálculos de medidas'!$C$2,Descontos!$E$1:$AA$47,Descontos!A25),0) -> 0
A31: =Datos!$G$19 -> 0 | B31: Pieza 2 | C31: =IF(A31<>0,HLOOKUP('Cálculos de medidas'!$C$2,Descontos!$E$1:$AA$47,Descontos!A26),0) -> 0
A32: =Datos!$G$19 -> 0 | B32: Pieza 3 | C32: =IF(A32<>0,HLOOKUP('Cálculos de medidas'!$C$2,Descontos!$E$1:$AA$47,Descontos!A27),0) -> 0
A33: =Datos!$G$19 -> 0 | B33: Pieza 4 | C33: =IF(A33<>0,HLOOKUP('Cálculos de medidas'!$C$2,Descontos!$E$1:$AA$47,Descontos!A28),0) -> 0
A34: =Datos!$G$19 -> 0 | B34: Pieza 5 | C34: =IF(A34<>0,HLOOKUP('Cálculos de medidas'!$C$2,Descontos!$E$1:$AA$47,Descontos!A29),0) -> 0
A35: =Datos!$G$19 -> 0 | B35: Pieza 6 | C35: =IF(A35<>0,HLOOKUP('Cálculos de medidas'!$C$2,Descontos!$E$1:$AA$47,Descontos!A30),0) -> 0
A36: =Datos!$G$19 -> 0 | B36: Pieza 7 | C36: =IF(A36<>0,HLOOKUP('Cálculos de medidas'!$C$2,Descontos!$E$1:$AA$47,Descontos!A31),0) -> 0
A37: =Datos!$G$19 -> 0 | B37: Pieza 8 | C37: =IF(A37<>0,HLOOKUP('Cálculos de medidas'!$C$2,Descontos!$E$1:$AA$47,Descontos!A32),0) -> 0
A38: =Datos!$G$19 -> 0 | B38: Pieza 9 | C38: =IF(A38<>0,HLOOKUP('Cálculos de medidas'!$C$2,Descontos!$E$1:$AA$47,Descontos!A33),0) -> 0
A39: =Datos!$G$19 -> 0 | B39: Pieza 10 | C39: =IF(A39<>0,HLOOKUP('Cálculos de medidas'!$C$2,Descontos!$E$1:$AA$47,Descontos!A34),0) -> 0
A40: =Datos!$G$19 -> 0 | B40: Pieza 11 | C40: =IF(A40<>0,HLOOKUP('Cálculos de medidas'!$C$2,Descontos!$E$1:$AA$47,Descontos!A35),0) -> 0
A41: =Datos!$G$19 -> 0 | B41: Pieza 12 | C41: =IF(A41<>0,HLOOKUP('Cálculos de medidas'!$C$2,Descontos!$E$1:$AA$47,Descontos!A36),0) -> 0
... A51: =Datos!$G$19 -> 0 | B51: Pieza 22 | C51: =IF(A51<>0,HLOOKUP('Cálculos de medidas'!$C$2,Descontos!$E$1:$AA$47,Descontos!A46),0) -> 0
A53: OF | B53: ARTICULO | C53: CANTIDAD
A54: =Datos!$K$19 -> 0 | B54: =INDEX('M TELAS'!A:A,MATCH(Datos!C8,'M TELAS'!B:B,0)) -> #N/A | C54: =IFERROR('Medidas Toldo 3'!G9,0) -> 0
A55: =Datos!$K$19 -> 0
A56: =Datos!$K$19 -> 0 | B56: Pieza 1 | C56: =IF(A56<>0,HLOOKUP('Cálculos de medidas'!$C$2,Descontos!$E$1:$AA$47,Descontos!A25),0) -> 0
A57: =Datos!$K$19 -> 0 | B57: Pieza 2 | C57: =IF(A57<>0,HLOOKUP('Cálculos de medidas'!$C$2,Descontos!$E$1:$AA$47,Descontos!A26),0) -> 0
A58: =Datos!$K$19 -> 0 | B58: Pieza 3 | C58: =IF(A58<>0,HLOOKUP('Cálculos de medidas'!$C$2,Descontos!$E$1:$AA$47,Descontos!A27),0) -> 0
A59: =Datos!$K$19 -> 0 | B59: Pieza 4 | C59: =IF(A59<>0,HLOOKUP('Cálculos de medidas'!$C$2,Descontos!$E$1:$AA$47,Descontos!A28),0) -> 0
A60: =Datos!$K$19 -> 0 | B60: Pieza 5 | C60: =IF(A60<>0,HLOOKUP('Cálculos de medidas'!$C$2,Descontos!$E$1:$AA$47,Descontos!A29),0) -> 0
...

Sheet Cálculos de medidas
A2: =_xlfn.IFS(Datos!C12=110,"0",Datos!C12=130,"1",Datos!C12=150,"2") -> #N/A | B2: Código modelo: | C2: =_xlfn.CONCAT('Cálculos de medidas'!A2,'Cálculos de medidas'!A3,'Cálculos de medidas'!A4,'Cálculos de medidas'!A5,'Cálculos de medidas'!A6,) -> #N/A
A3: =IF(Datos!C13="SI","0","1") -> 1
A4: =_xlfn.IFS(Datos!C14="NO","0",Datos!C14="Pequeña","1",Datos!C14="Normal","2") -> #N/A
A5: =_xlfn.IFS(Datos!C15="Máquina","0",Datos!C15="Motor","1") -> #N/A
A6: =_xlfn.IFS(Datos!C16="NO","0",Datos!C16="SI","1") -> #N/A
A7: TOLDO 1
C8: Manual | D8: Entre paredes | F8: Desconto total | H8: Medida hueco | J8: Medida definitiva
B9: Tela | C9: =HLOOKUP($C$2,Descontos!$E$1:$AA$18,6) -> #N/A | D9: =IF(Datos!$C$17="SI",0.6,0) -> 0 | F9: =C9+D9 -> #N/A | H9: =Datos!$C$34 -> 0 | J9: =H9-F9 -> #N/A
B10: Caída | H10: =MIN('Cálculos de escuadrado'!G3,'Cálculos de escuadrado'!G4) -> #DIV/0! | J10: =H10-F10 -> #DIV/0!
B11: Cofre | C11: =HLOOKUP($C$2,Descontos!$E$1:$AA$18,8) -> #N/A | D11: =IF(Datos!$C$17="SI",0.6,0) -> 0 | F11: =C11+D11 -> #N/A | H11: =Datos!$C$34 -> 0 | J11: =H11-F11 -> #N/A
B12: Tubo enrolle | C12: =HLOOKUP($C$2,Descontos!$E$1:$AA$18,9) -> #N/A | D12: =IF(Datos!$C$17="SI",0.6,0) -> 0 | F12: =C12+D12 -> #N/A | H12: =Datos!$C$34 -> 0 | J12: =H12-F12 -> #N/A
B13: Tubo carga | C13: =HLOOKUP($C$2,Descontos!$E$1:$AA$18,10) -> #N/A | D13: =IF(Datos!$C$17="SI",0.6,0) -> 0 | F13: =C13+D13 -> #N/A | H13: =Datos!$C$34 -> 0 | J13: =H13-F13 -> #N/A
B14: Lastre | C14: =HLOOKUP($C$2,Descontos!$E$1:$AA$18,11) -> #N/A | D14: =IF(Datos!$C$17="SI",0.6,0) -> 0 | F14: =C14+D14 -> #N/A | H14: =Datos!$C$34 -> 0 | J14: =H14-F14 -> #N/A
A16: MFI | B16: Perfil de guía pared | C16: =HLOOKUP($C$2,Descontos!$E$1:$AA$18,14) -> #N/A | F16: =C16+D16 -> #N/A | H16: ='Cálculos de escuadrado'!$G$3 -> #DIV/0! | J16: =H16-F16 -> #DIV/0!
A17: MFI | B17: Perfil guía interior ZIP Pared | C17: =HLOOKUP($C$2,Descontos!$E$1:$AA$18,16) -> #N/A | F17: =C17+D17 -> #N/A | H17: ='Cálculos de escuadrado'!$G$3 -> #DIV/0! | J17: =H17-F17 -> #DIV/0!
A18: MFI | B18: Guía compensación pared | C18: =HLOOKUP($C$2,Descontos!$E$1:$AA$18,12) -> #N/A | F18: =C18+D18 -> #N/A | H18: =Datos!C23 -> 0 | J18: =H18-F18 -> #N/A
A20: MFD | B20: Perfil de guía pared | C20: =HLOOKUP($C$2,Descontos!$E$1:$AA$18,14) -> #N/A | F20: =C20+D20 -> #N/A | H20: ='Cálculos de escuadrado'!$G$4 -> #DIV/0! | J20: =H20-F20 -> #DIV/0!
A21: MFD | B21: Perfil guía interior ZIP Pared | C21: =HLOOKUP($C$2,Descontos!$E$1:$AA$18,16) -> #N/A | F21: =C21+D21 -> #N/A | H21: ='Cálculos de escuadrado'!$G$4 -> #DIV/0! | J21: =H21-F21 -> #DIV/0!
A22: MFD | B22: Guía compensación pared | C22: =HLOOKUP($C$2,Descontos!$E$1:$AA$18,12) -> #N/A | F22: =C22+D22 -> #N/A | H22: =Datos!C27 -> 0 | J22: =H22-F22 -> #N/A
B24: Guía compensación techo | C24: =HLOOKUP($C$2,Descontos!$E$1:$AA$18,13) -> #N/A | D24: =IF(Datos!$C$17="SI",0.6,0) -> 0 | F24: =C24+D24 -> #N/A | J24: =H24-F24 -> #N/A
B25: Perfil de guía techo | C25: =HLOOKUP($C$2,Descontos!$E$1:$AA$18,15) -> #N/A | D25: =IF(Datos!$C$17="SI",0.6,0) -> 0 | F25: =C25+D25 -> #N/A | J25: =H25-F25 -> #N/A
B26: Perfil guía interior ZIP Techo | C26: =HLOOKUP($C$2,Descontos!$E$1:$AA$18,17) -> #N/A | D26: =IF(Datos!$C$17="SI",0.6,0) -> 0 | F26: =C26+D26 -> #N/A | J26: =H26-F26 -> #N/A
B28: Terminal compensador | D28: =IF(Datos!$C$17="SI",0.6,0) -> 0 | F28: =C28+D28 -> 0 | J28: =H28-F28 -> 0
A31: TOLDO 2
C32: Manual | D32: Entre paredes | F32: Desconto total | H32: Medida hueco | J32: Medida definitiva
B33: Tela | C33: =HLOOKUP($C$2,Descontos!$E$1:$AA$18,6) -> #N/A | D33: =IF(Datos!$C$17="SI",0.6,0) -> 0 | F33: =C33+D33 -> #N/A | H33: =Datos!$G$34 -> 0 | J33: =H33-F33 -> #N/A
B34: Caída | H34: =MIN('Cálculos de escuadrado'!G7,'Cálculos de escuadrado'!G8) -> #DIV/0! | J34: =H34-F34 -> #DIV/0!
B35: Cofre | C35: =HLOOKUP($C$2,Descontos!$E$1:$AA$18,8) -> #N/A | D35: =IF(Datos!$C$17="SI",0.6,0) -> 0 | F35: =C35+D35 -> #N/A | H35: =Datos!$G$34 -> 0 | J35: =H35-F35 -> #N/A
B36: Tubo enrolle | C36: =HLOOKUP($C$2,Descontos!$E$1:$AA$18,9) -> #N/A | D36: =IF(Datos!$C$17="SI",0.6,0) -> 0 | F36: =C36+D36 -> #N/A | H36: =Datos!$G$34 -> 0 | J36: =H36-F36 -> #N/A
B37: Tubo carga | C37: =HLOOKUP($C$2,Descontos!$E$1:$AA$18,10) -> #N/A | D37: =IF(Datos!$C$17="SI",0.6,0) -> 0 | F37: =C37+D37 -> #N/A | H37: =Datos!$G$34 -> 0 | J37: =H37-F37 -> #N/A
B38: Lastre | C38: =HLOOKUP($C$2,Descontos!$E$1:$AA$18,11) -> #N/A | D38: =IF(Datos!$C$17="SI",0.6,0) -> 0 | F38: =C38+D38 -> #N/A | H38: =Datos!$G$34 -> 0 | J38: =H38-F38 -> #N/A
A40: MFI | B40: Perfil de guía pared | C40: =HLOOKUP($C$2,Descontos!$E$1:$AA$18,14) -> #N/A | F40: =C40+D40 -> #N/A | H40: ='Cálculos de escuadrado'!$G$3 -> #DIV/0! | J40: =H40-F40 -> #DIV/0!
A41: MFI | B41: Perfil guía interior ZIP Pared | C41: =HLOOKUP($C$2,Descontos!$E$1:$AA$18,16) -> #N/A | F41: =C41+D41 -> #N/A | H41: ='Cálculos de escuadrado'!$G$3 -> #DIV/0! | J41: =H41-F41 -> #DIV/0!
A42: MFI | B42: Guía compensación pared | C42: =HLOOKUP($C$2,Descontos!$E$1:$AA$18,12) -> #N/A | F42: =C42+D42 -> #N/A | H42: =Datos!C49 -> 0 | J42: =H42-F42 -> #N/A
A44: MFD | B44: Perfil de guía pared | C44: =HLOOKUP($C$2,Descontos!$E$1:$AA$18,14) -> #N/A | F44: =C44+D44 -> #N/A | H44: ='Cálculos de escuadrado'!$G$4 -> #DIV/0! | J44: =H44-F44 -> #DIV/0!
A45: MFD | B45: Perfil guía interior ZIP Pared | C45: =HLOOKUP($C$2,Descontos!$E$1:$AA$18,16) -> #N/A | F45: =C45+D45 -> #N/A | H45: ='Cálculos de escuadrado'!$G$4 -> #DIV/0! | J45: =H45-F45 -> #DIV/0!
A46: MFD | B46: Guía compensación pared | C46: =HLOOKUP($C$2,Descontos!$E$1:$AA$18,12) -> #N/A | F46: =C46+D46 -> #N/A | H46: =Datos!C53 -> 0 | J46: =H46-F46 -> #N/A
B48: Guía compensación techo | C48: =HLOOKUP($C$2,Descontos!$E$1:$AA$18,13) -> #N/A | D48: =IF(Datos!$C$17="SI",0.6,0) -> 0 | F48: =C48+D48 -> #N/A | J48: =H48-F48 -> #N/A
B49: Perfil de guía techo | C49: =HLOOKUP($C$2,Descontos!$E$1:$AA$18,15) -> #N/A | D49: =IF(Datos!$C$17="SI",0.6,0) -> 0 | F49: =C49+D49 -> #N/A | J49: =H49-F49 -> #N/A
B50: Perfil guía interior ZIP Techo | C50: =HLOOKUP($C$2,Descontos!$E$1:$AA$18,17) -> #N/A | D50: =IF(Datos!$C$17="SI",0.6,0) -> 0 | F50: =C50+D50 -> #N/A | J50: =H50-F50 -> #N/A
...

Sheet Características
A1: Modelo de toldo | C1: Lleva cofre | E1: Guía | G1: Mecanismo | I1: Entre paredes | K1: SWBS | M1: Cristal | O1: Medidas cristal
A2: 110 | C2: SI | E2: NO | G2: Máquina | I2: NO | K2: SI | M2: SI | O2: 0
A3: 130 | C3: NO | E3: Pequeña | G3: Motor | I3: SI | K3: NO | M3: NO | O3: 200
A4: 150 | E4: Normal | O4: 250
O5: 300
O6: 350
O7: 400
O8: 450
O9: 500
O10: 550
O11: 600
O12: 650
O13: 700
N15: Cristal Toldo 1 | O15: {=MIN(IF(Tabla8[Medidas cristal]>'Medidas Toldo 1'!F9,Tabla8[Medidas cristal]))} -> 200
N16: Cristal Toldo 2 | O16: {=MIN(IF(Tabla8[Medidas cristal]>'Medidas Toldo 2'!F9,Tabla8[Medidas cristal]))} -> 200
N17: Cristal Toldo 3 | O17: {=MIN(IF(Tabla8[Medidas cristal]>'Medidas Toldo 3'!F9,Tabla8[Medidas cristal]))} -> 200
N18: Cristal Toldo 4 | O18: {=MIN(IF(Tabla8[Medidas cristal]>'Medidas Toldo 4'!F9,Tabla8[Medidas cristal]))} -> 200
